Workbook
Name Administrador_SARLAFT: OFFSET(INDIRECT('OTRAS 1'!A$29),0,0,COUNTIF(OtrasApp[[#All],[App]],'OTRAS 1'!$B$22 & "-" &'OTRAS 1'!A$33))
Name AppIseries: Tabla11[App Iseries]
Name AppIseries: Tabla11[App Iseries]
Name AppIseries: Tabla11[App Iseries]
Name AppLaserfiche: Tabla3[AppLaserfiche]
Name AppLaserfiche: Tabla3[AppLaserfiche]
Name AppSalud: 'SALUD 1'!$O$252:$P$254
Name AppSalud2: 'SALUD 1'!$R$252:$T$271
Name Area_Eflow: SharePoint!$BS$2:$BS$27
Name ciudad: '[1]PERSONAL MEDICO'!$AU$1000008:$AV$1001048
Name COD_ESP: '[1]PERSONAL MEDICO'!$AM$1000008:$AN$1000108
Name Deposito: Tabla32587[[DEPOSITO ]]
Name ECredisystem: SharePoint!$AS$2:$AS$23
Name ESPECIALIDAD: '[1]PERSONAL MEDICO'!$AM$1000008:$AM$1000109
Name EstadoCivil: Tabla12[EstadoCivil]
Name EstadoCivil: Tabla12[EstadoCivil]
Name FacturadorSAC: SharePoint!$U$2:$U$4
Name Fosfec: SharePoint!$O$2:$O$4
Name FuncTPNET1: OFFSET(INDIRECT('MEDICAMENTOS 1'!A$23),0,0,COUNTIF('MEDICAMENTOS 1'!$R$250:$R$279,'MEDICAMENTOS 1'!A$26))
Name FuncTPNET2: OFFSET(INDIRECT('MEDICAMENTOS 1'!A$24),0,0,COUNTIF('MEDICAMENTOS 1'!$M$250:$M$303,'MEDICAMENTOS 1'!A$27))
Name Grup_Eflow: Tabla2[GRUPO-EFLOW]
Name Grup_Eflow: Tabla2[GRUPO-EFLOW]
Name GrupSeven: SharePoint!$BC$2:$BC$83
Name IPS_Salud: 'SALUD 1'!$L$252:$M$288
Name Jedox: SharePoint!$S$2:$S$7
Name LinkAppFinanciera: Navegación!$B$62
Name LinkAppMedicamentos: Navegación!$B$41
Name LinkAppOtras: Navegación!$B$77
Name LinkAppPrivilegiados: Navegación!$A$100
Name LinkAppRecreacion: Navegación!$B$55
Name LinkAppSalud: Navegación!$A$35
Name LinkAppSAP: Navegación!$B$36
Name LinkAppVivienda: Navegación!$B$72
Name LinkAppWindows: Navegación!$A$24
Name LinkMasivos: Navegación!$C$102
Name lista1: 'SALUD 1'!$M$128:$M$146
Name Ofc_Eflow: SharePoint!$BO$2:$BO$25
Name P_Enterprise: SharePoint!$Y$2:$Y$8
Name P_EvenTeatro: Tabla13[Perfil Ev Teatro]
Name P_EvenTeatro: Tabla13[Perfil Ev Teatro]
Name P_EvenTeatro: Tabla13[Perfil Ev Teatro]
Name P_Hercules: OFFSET(INDIRECT('RECREACION 1'!#REF!),0,0,COUNTIF(RolesNew[#All],'RECREACION 1'!#REF!))
Name P_Hercules: OFFSET(INDIRECT('RECREACION 5'!$D$23),0,0,COUNTIF(RolesNew117118119[#All],'RECREACION 5'!$B$22))
Name P_Hercules: OFFSET(INDIRECT('RECREACION 1'!#REF!),0,0,COUNTIF(RolesNew[#All],'RECREACION 1'!#REF!))
Name P_Iseries: SharePoint!$BM$2:$BM$43
Name P_LASERFICHE: OFFSET(INDIRECT('OTRAS 10'!A$23),0,0,COUNTIF(OtrasApp141142143144145146147148149150151[[#All],[App]],'OTRAS 10'!$B$22 & "-" & 'OTRAS 10'!A$27))
Name P_LASERFICHE: OFFSET(INDIRECT('OTRAS 1'!A$78),0,0,COUNTIF(OtrasApp141142[[#All],[App]],'OTRAS 1'!$B$76 & "-" & 'OTRAS 1'!A$82))
Name P_LASERFICHE: OFFSET(INDIRECT('OTRAS 1'!A$78),0,0,COUNTIF(OtrasApp[[#All],[App]],'OTRAS 1'!#REF! & "-" & 'OTRAS 1'!A$82))
Name P_Q10: OFFSET(INDIRECT('OTRAS 13'!A$23),0,0,COUNTIF(OtrasApp141142143144145146147148149150151152153154[[#All],[App]],'OTRAS 13'!$B$22 & "-" & 'OTRAS 13'!A$33))
Name P_Q10: OFFSET(INDIRECT('OTRAS 1'!A$97),0,0,COUNTIF(OtrasApp141142[[#All],[App]],'OTRAS 1'!$B$95 & "-" & 'OTRAS 1'!A$107))
Name P_Q10: OFFSET(INDIRECT('OTRAS 1'!A$97),0,0,COUNTIF(OtrasApp[[#All],[App]],'OTRAS 1'!#REF! & "-" & 'OTRAS 1'!A$107))
Name P_Recreacion: 'RECREACION 1'!$L$250:$M$322
Name P_SAS: SharePoint!$BE$2:$BE$4
Name P_SEVEN: SharePoint!$BA$2:$BA$7
Name P_TM1: SharePoint!$BG$2:$BG$4
Name P_WebFamisanar: SharePoint!$AE$2:$AE$11
Name PagosTIC: Tabla65[Pagos TIC]
Name PagosTIC: Tabla65[Pagos TIC]
Name PagosTIC: Tabla65[Pagos TIC]
Name Perfil_NAPSE_Director: OFFSET(INDIRECT('MEDICAMENTOS 10'!A$28),0,0,COUNTIF(P_NAPSE[],'MEDICAMENTOS 10'!$D$31))

Sheet Perfiles ISERIES
A6: Medicamentos SIGED | C6: SALUD
A7: Unidad Reaprovisionamiento | C7: Cajero
A8: Auxiliar Compras Costo Promedio | C8: Recaudos
A9: Master Siged | C9: Reservas CC
A10: Analista Almacenamiento | C10: Grupo de Apoyo
A11: Analista Centro Distribución Medicamentos
A12: Auxiliar Recibo Inventario
A13: Auxiliar Recibo Inventario Costo Promedio
A14: Jefe Sección Almacenamiento
A15: Revisor Documentos Cendis
A16: Supervisores Bodega
A17: Analista Compras Medicamentos
A18: Jefe Producto Medicamentos
A19: Departamento Técnico
A20: Consulta Ventas
A21: Monitor Droguerías (Regente)
A22: Supervisores Punto De Venta
... A26: Revisor Movimiento Mercancias

Sheet Menu

Sheet INFORME
A1: Grupo | B1: App | C1: Cant. Novedades
A2: Windows | B2: Windows | C2: ='WINDOWS 1'!$DZ$22 -> 1
B3: Share point | C3: ='WINDOWS 1'!$DZ$31 -> 0
B4: Buzon Personal | C4: ='WINDOWS 1'!$DZ$38 -> 0
B5: Buzon de Area | C5: ='WINDOWS 1'!$DZ$41 -> 0
A6: Salud | B6: Integra - BreakPoint Famisanar | C6: ='SALUD 1'!$DZ$26 -> 0
B7: PANA - NEPS | C7: ='SALUD 1'!$DZ$42 -> #REF!
B8: RETHUS | C8: ='SALUD 1'!$DZ$51 -> #REF!
B9: ZERO | C9: ='SALUD 1'!$DZ$62 -> #REF!
B10: Enterprise | C10: ='SALUD 1'!$DZ$72 -> #REF!
B11: Sycyproh | C11: ='SALUD 1'!$DZ$82 -> #REF!
B12: SIGESA | C12: ='SALUD 1'!$DZ$96 -> #REF!
B13: ISERIES | C13: ='SALUD 1'!$DZ$102 -> #REF!
B14: Web Famisanar en Linea | C14: ='SALUD 1'!$DZ$106 -> #REF!
B15: RUAF | C15: ='SALUD 1'!$DZ$110 -> #REF!
A16: SAP | B16: SAP | C16: ='SAP 1'!$DZ$22 -> 0
B17: Solucion WEB Roles SAP | C17: ='SAP 1'!$DZ$30 -> #REF!
B18: Cash Journal | C18: ='SAP 1'!$DZ$34 -> #REF!
B19: Facturador SD | C19: ='SAP 1'!$DZ$40 -> #REF!
B20: Liberacion Pedidos | C20: ='SAP 1'!$DZ$43 -> #REF!
A21: Medicamentos | B21: TPNET | C21: ='MEDICAMENTOS 1'!$DZ$30+'MEDICAMENTOS 1'!$DZ$32+'MEDICAMENTOS 1'!$DZ$34+'MEDICAMENTOS 1'!$DZ$36+'MEDICAMENTOS 1'!$DZ$38+'MEDICAMENTOS 1'!$DZ$40 -> 0
B22: WMS | C22: ='MEDICAMENTOS 1'!$DZ$42 -> 0
B23: SIGED | C23: ='MEDICAMENTOS 1'!$DZ$50 -> #REF!
B24: Medicar | C24: ='MEDICAMENTOS 1'!$DZ$54 -> #REF!
B25: MULTICANAL | C25: ='MEDICAMENTOS 1'!$DZ$56 -> 0
B26: POS IBM | C26: ='MEDICAMENTOS 1'!$DZ$58 -> #REF!
B27: Web Famisanar en Linea | C27: ='MEDICAMENTOS 1'!$DZ$60 -> 0
A28: Recreación | B28: New Plan | C28: ='RECREACION 1'!$DZ$24 -> 0
B29: New Hotel | C29: ='RECREACION 1'!$DZ$29 -> 0
B30: New POS | C30: ='RECREACION 1'!$DZ$34 -> 0
B31: New Stock | C31: ='RECREACION 1'!$DZ$39 -> 0
B32: New Caja | C32: ='RECREACION 1'!$DZ$44 -> 0
B33: SAC | C33: ='RECREACION 1'!$DZ$49 -> 0
B34: Silvernest | C34: ='RECREACION 1'!$DZ$55 -> #REF!
B35: Zeus Online | C35: ='RECREACION 1'!$DZ$60 -> #REF!
B36: Hercules | C36: ='RECREACION 1'!$DZ$65 -> #REF!
A37: Financiera | B37: E-credisystem | C37: ='FINANCIERA 1'!$DZ$23 -> 0
B38: SEVEN | C38: ='FINANCIERA 1'!$DZ$27 -> #REF!
B39: SAS | C39: ='FINANCIERA 1'!$DZ$39 -> #REF!
B40: TM1 | C40: ='FINANCIERA 1'!$DZ$43 -> #REF!
...

Sheet WINDOWS 1
K1: 2958465
C2: FORMATO: GESTIÓN DE IDENTIDADES
F3: DOCUMENTO USO INTERNO
B5: Las celdas resaltadas en Naranja son campos obligatorios del Formato.
B6: Información Usuarios | D6: Usuario 1 | E6: Usuario 2 | F6: Usuario 3 | G6: Usuario 4 | H6: Usuario 5 | I6: Usuario 6
B7: Tipo de documento | D7: =IF(Navegación!D7<>"",Navegación!D7,"") -> Cédula Ciudadanía | E7: =IF(Navegación!E7<>"",Navegación!E7,"") | F7: =IF(Navegación!F7<>"",Navegación!F7,"") | G7: =IF(Navegación!G7<>"",Navegación!G7,"") | H7: =IF(Navegación!H7<>"",Navegación!H7,"") | I7: =IF(Navegación!I7<>"",Navegación!I7,"")
B8: Identificación | D8: =IF(Navegación!D8<>"",Navegación!D8,"") -> 1001089595 | E8: =IF(Navegación!E8<>"",Navegación!E8,"") | F8: =IF(Navegación!F8<>"",Navegación!F8,"") | G8: =IF(Navegación!G8<>"",Navegación!G8,"") | H8: =IF(Navegación!H8<>"",Navegación!H8,"") | I8: =IF(Navegación!I8<>"",Navegación!I8,"")
B9: Nombres completos | D9: =IF(Navegación!D9<>"",Navegación!D9,"") -> JUAN PABLO | E9: =IF(Navegación!E9<>"",Navegación!E9,"") | F9: =IF(Navegación!F9<>"",Navegación!F9,"") | G9: =IF(Navegación!G9<>"",Navegación!G9,"") | H9: =IF(Navegación!H9<>"",Navegación!H9,"") | I9: =IF(Navegación!I9<>"",Navegación!I9,"")
B10: Apellidos completos | D10: =IF(Navegación!D10<>"",Navegación!D10,"") -> CAMPO TELLEZ | E10: =IF(Navegación!E10<>"",Navegación!E10,"") | F10: =IF(Navegación!F10<>"",Navegación!F10,"") | G10: =IF(Navegación!G10<>"",Navegación!G10,"") | H10: =IF(Navegación!H10<>"",Navegación!H10,"") | I10: =IF(Navegación!I10<>"",Navegación!I10,"")
B11: Centro de costo | D11: =IF(Navegación!D11<>"",Navegación!D11,"") -> 856 | E11: =IF(Navegación!E11<>"",Navegación!E11,"") | F11: =IF(Navegación!F11<>"",Navegación!F11,"") | G11: =IF(Navegación!G11<>"",Navegación!G11,"") | H11: =IF(Navegación!H11<>"",Navegación!H11,"") | I11: =IF(Navegación!I11<>"",Navegación!I11,"")
B12: Teléfono/Extensión de contacto del usuario | D12: =IF(Navegación!D12<>"",Navegación!D12,"") | E12: =IF(Navegación!E12<>"",Navegación!E12,"") | F12: =IF(Navegación!F12<>"",Navegación!F12,"") | G12: =IF(Navegación!G12<>"",Navegación!G12,"") | H12: =IF(Navegación!H12<>"",Navegación!H12,"") | I12: =IF(Navegación!I12<>"",Navegación!I12,"")
B13: Celular | D13: =IF(Navegación!D13<>"",Navegación!D13,"") -> 3150727969 | E13: =IF(Navegación!E13<>"",Navegación!E13,"") | F13: =IF(Navegación!F13<>"",Navegación!F13,"") | G13: =IF(Navegación!G13<>"",Navegación!G13,"") | H13: =IF(Navegación!H13<>"",Navegación!H13,"") | I13: =IF(Navegación!I13<>"",Navegación!I13,"")
B14: Dependencia | D14: =IF(Navegación!D14<>"",Navegación!D14,"") -> Gobierno | E14: =IF(Navegación!E14<>"",Navegación!E14,"") | F14: =IF(Navegación!F14<>"",Navegación!F14,"") | G14: =IF(Navegación!G14<>"",Navegación!G14,"") | H14: =IF(Navegación!H14<>"",Navegación!H14,"") | I14: =IF(Navegación!I14<>"",Navegación!I14,"")
B15: Cargo | D15: =IF(Navegación!D15<>"",Navegación!D15,"") -> Aprendiz Universitario | E15: =IF(Navegación!E15<>"",Navegación!E15,"") | F15: =IF(Navegación!F15<>"",Navegación!F15,"") | G15: =IF(Navegación!G15<>"",Navegación!G15,"") | H15: =IF(Navegación!H15<>"",Navegación!H15,"") | I15: =IF(Navegación!I15<>"",Navegación!I15,"")
B16: Empleado Cafam o Externo | D16: =IF(Navegación!D16<>"",Navegación!D16,"") -> Empleado CAFAM | E16: =IF(Navegación!E16<>"",Navegación!E16,"") | F16: =IF(Navegación!F16<>"",Navegación!F16,"") | G16: =IF(Navegación!G16<>"",Navegación!G16,"") | H16: =IF(Navegación!H16<>"",Navegación!H16,"") | I16: =IF(Navegación!I16<>"",Navegación!I16,"")
B17: Nombre de la empresa cuando es Externo | D17: =IF(Navegación!D17<>"",Navegación!D17,"") | E17: =IF(Navegación!E17<>"",Navegación!E17,"") | F17: =IF(Navegación!F17<>"",Navegación!F17,"") | G17: =IF(Navegación!G17<>"",Navegación!G17,"") | H17: =IF(Navegación!H17<>"",Navegación!H17,"") | I17: =IF(Navegación!I17<>"",Navegación!I17,"")
B18: Fecha inicio contrato: | D18: =IF(Navegación!D18<>"",Navegación!D18,"") -> 45849 | E18: =IF(Navegación!E18<>"",Navegación!E18,"") | F18: =IF(Navegación!F18<>"",Navegación!F18,"") | G18: =IF(Navegación!G18<>"",Navegación!G18,"") | H18: =IF(Navegación!H18<>"",Navegación!H18,"") | I18: =IF(Navegación!I18<>"",Navegación!I18,"")
B19: Fecha finalización contrato: (Si es indefinido escribir 31/12/9999) | D19: =IF(Navegación!D19<>"",Navegación!D19,"") | E19: =IF(Navegación!E19<>"",Navegación!E19,"") | F19: =IF(Navegación!F19<>"",Navegación!F19,"") | G19: =IF(Navegación!G19<>"",Navegación!G19,"") | H19: =IF(Navegación!H19<>"",Navegación!H19,"") | I19: =IF(Navegación!I19<>"",Navegación!I19,"")
B21: Requerimientos Plataforma Windows | D21: =IF(DZ22>0,Navegación!$E$21,"") -> Esta aplicación solo requiere VoBo de su Jefatura
B22: Novedad Windows (Crear/Modificar/Baja) | D22: Crear | DZ22: =COUNTIF(D22:I22,"<>") -> 1
B23: Alias del Usuario Windows (a modificar o dar de baja)
B24: Accesos adicionales Windows
B25: Accesos VPN | D25: Aplicaciones
B26: Detalle Acceso a VPN (Aplicaciones) Nombre de Equipo (Escritorio Remoto) | D26: wso2/aro
B27: Acceso a recursos compartidos (\\nombre_servidor\nombre_recurso)
B28: Permisos a Almacenamiento Externo (relacionar los sitios especificos en fila "Permisos y accesos adicionales") - Adjunte autorizacion de Oficial de Seguridad
B29: Permisos y accesos adicionales
B31: Observaciones | C31: Grupo de recursos por suscripción: az-trv-prod-suscripcion - az-trv-prd-rg-apim az-hub-devqa-suscripcion - az-hub-devqa-rg-security-00
B37: APROBADOR POR: Jefe Dpto. Servicios Compartidos | F37: ='Control de cambios'!$A$14 -> V20 de 26/09/2023 | I37: ="Pág. " &Navegación!B21 & " de " &Navegación!$B$102 -> Pág. 1 de 54

Sheet Instructivo
A1: Instructivo Formato Gestión de Identidades
A3: Es un único formato que debe ser utilizado para realizar los requerimientos de usuarios y accesos a los diferentes sistemas de información. Este formato deberá ser remitido a la mesa de servicio con las autorizaciones correspondientes. NO es aceptable la copia de perfiles, es decir que las solicitudes se remitan bajo el parámetro "con los mismos perfiles de una persona", se debe partir del mínimo privilegio.
A5: Definiciones
A6: Alta: Crear usuario
A7: Modificación: Modificar un usuario
A8: Bloqueo - Baja: Deshabilitar usuario / Eliminar usuario (En algunos aplicativos por buenas practicas no se elimina el usuario, solo se bloquea)
A9: Ampliación Vigencia: El usuario tenia una fecha de contrato y se requiere ampliar esta fecha
A11: Información Solicitante
A12: Información obligatoria. Todo requerimiento debe ser remitido a la mesa de servicio con el visto bueno de la jefatura de la Unidad Estratégica de Servicio que requiere el acceso, de acuerdo al Orden Jerárquico del artículo 56 del Reglamento interno de trabajo, es decir (DIRECTOR ADMINISTRATIVO, SUBDIRECTORES, JEFES DEPARTAMENTO, JEFES SECCION – ADMINISTRADORES, JEFES DE AREA, SUPERVISORES – COORDINADORES).
A14: Información Usuarios
A15: Información obligatoria. La identificación es un campo numérico que debe llenarse sin puntos ni comas. Los nombres y apellidos deben ser completos y escritos como figuran en el documento de identificación. El centro de costo y dependencia del funcionario o de la dependencia para la cual trabaja la persona externa, de igual manera indicar el cargo. Indicar un número de contacto del usuario a quien se le va a asignar los privilegios El campo empleado Cafam o Externo, cuando el usuario es Externo se debe escribir el nombre de la empresa o proveedor Se debe definir fecha inicio de contrato y fecha fin, cuando se tenga contrato indefinido coloque 31/12/9999. Ningun funcionario externo puede tener vigencia Indefinida. Si require incluir mas usuarios, proceda a copiar la ultima columna y utiice la opcion "Insertar celdas copiadas".
A17: Requerimientos Plataforma Windows
... A32: CashJornal es la caja de SAP que se utiliza para pagos de subsidio y educación, a este modulo tienen acceso únicamente las centrales de servicio (Supervisores, revisores y cajeros). Cajas para asignar: En estos campos se debe indicar si el acceso se requiere para Educación, Subsidio o Ambas. Función a desempeñar: Indique el rol o función que va a desempeñar, es decir si es Cajero o Revisor. Corresponde a reemplazo o asignacion nueva: seleccione la opcion identificando la que corresponda. Nombre Sucursal: Describa el nombre de la sucursal a la cual estara asignado el usuario. Si se trata de un traslado por favor indicar el número y nombre de la caja que tenía asignada. Esto con el fin de facilitar la asignacion de la caja

Sheet WINDOWS 2
K1: 2958465
C2: FORMATO: GESTIÓN DE IDENTIDADES
F3: DOCUMENTO USO INTERNO
B5: Las celdas resaltadas en Naranja son campos obligatorios del Formato.
B6: Información Usuarios | D6: Usuario 1 | E6: Usuario 2 | F6: Usuario 3 | G6: Usuario 4 | H6: Usuario 5 | I6: Usuario 6
B7: Tipo de documento | D7: =IF(Navegación!D7<>"",Navegación!D7,"") -> Cédula Ciudadanía | E7: =IF(Navegación!E7<>"",Navegación!E7,"") | F7: =IF(Navegación!F7<>"",Navegación!F7,"") | G7: =IF(Navegación!G7<>"",Navegación!G7,"") | H7: =IF(Navegación!H7<>"",Navegación!H7,"") | I7: =IF(Navegación!I7<>"",Navegación!I7,"")
B8: Identificación | D8: =IF(Navegación!D8<>"",Navegación!D8,"") -> 1001089595 | E8: =IF(Navegación!E8<>"",Navegación!E8,"") | F8: =IF(Navegación!F8<>"",Navegación!F8,"") | G8: =IF(Navegación!G8<>"",Navegación!G8,"") | H8: =IF(Navegación!H8<>"",Navegación!H8,"") | I8: =IF(Navegación!I8<>"",Navegación!I8,"")
B9: Nombres completos | D9: =IF(Navegación!D9<>"",Navegación!D9,"") -> JUAN PABLO | E9: =IF(Navegación!E9<>"",Navegación!E9,"") | F9: =IF(Navegación!F9<>"",Navegación!F9,"") | G9: =IF(Navegación!G9<>"",Navegación!G9,"") | H9: =IF(Navegación!H9<>"",Navegación!H9,"") | I9: =IF(Navegación!I9<>"",Navegación!I9,"")
B10: Apellidos completos | D10: =IF(Navegación!D10<>"",Navegación!D10,"") -> CAMPO TELLEZ | E10: =IF(Navegación!E10<>"",Navegación!E10,"") | F10: =IF(Navegación!F10<>"",Navegación!F10,"") | G10: =IF(Navegación!G10<>"",Navegación!G10,"") | H10: =IF(Navegación!H10<>"",Navegación!H10,"") | I10: =IF(Navegación!I10<>"",Navegación!I10,"")
B11: Centro de costo | D11: =IF(Navegación!D11<>"",Navegación!D11,"") -> 856 | E11: =IF(Navegación!E11<>"",Navegación!E11,"") | F11: =IF(Navegación!F11<>"",Navegación!F11,"") | G11: =IF(Navegación!G11<>"",Navegación!G11,"") | H11: =IF(Navegación!H11<>"",Navegación!H11,"") | I11: =IF(Navegación!I11<>"",Navegación!I11,"")
B12: Teléfono/Extensión de contacto del usuario | D12: =IF(Navegación!D12<>"",Navegación!D12,"") | E12: =IF(Navegación!E12<>"",Navegación!E12,"") | F12: =IF(Navegación!F12<>"",Navegación!F12,"") | G12: =IF(Navegación!G12<>"",Navegación!G12,"") | H12: =IF(Navegación!H12<>"",Navegación!H12,"") | I12: =IF(Navegación!I12<>"",Navegación!I12,"")
B13: Celular | D13: =IF(Navegación!D13<>"",Navegación!D13,"") -> 3150727969 | E13: =IF(Navegación!E13<>"",Navegación!E13,"") | F13: =IF(Navegación!F13<>"",Navegación!F13,"") | G13: =IF(Navegación!G13<>"",Navegación!G13,"") | H13: =IF(Navegación!H13<>"",Navegación!H13,"") | I13: =IF(Navegación!I13<>"",Navegación!I13,"")
B14: Dependencia | D14: =IF(Navegación!D14<>"",Navegación!D14,"") -> Gobierno | E14: =IF(Navegación!E14<>"",Navegación!E14,"") | F14: =IF(Navegación!F14<>"",Navegación!F14,"") | G14: =IF(Navegación!G14<>"",Navegación!G14,"") | H14: =IF(Navegación!H14<>"",Navegación!H14,"") | I14: =IF(Navegación!I14<>"",Navegación!I14,"")
B15: Cargo | D15: =IF(Navegación!D15<>"",Navegación!D15,"") -> Aprendiz Universitario | E15: =IF(Navegación!E15<>"",Navegación!E15,"") | F15: =IF(Navegación!F15<>"",Navegación!F15,"") | G15: =IF(Navegación!G15<>"",Navegación!G15,"") | H15: =IF(Navegación!H15<>"",Navegación!H15,"") | I15: =IF(Navegación!I15<>"",Navegación!I15,"")
B16: Empleado Cafam o Externo | D16: =IF(Navegación!D16<>"",Navegación!D16,"") -> Empleado CAFAM | E16: =IF(Navegación!E16<>"",Navegación!E16,"") | F16: =IF(Navegación!F16<>"",Navegación!F16,"") | G16: =IF(Navegación!G16<>"",Navegación!G16,"") | H16: =IF(Navegación!H16<>"",Navegación!H16,"") | I16: =IF(Navegación!I16<>"",Navegación!I16,"")
B17: Nombre de la empresa cuando es Externo | D17: =IF(Navegación!D17<>"",Navegación!D17,"") | E17: =IF(Navegación!E17<>"",Navegación!E17,"") | F17: =IF(Navegación!F17<>"",Navegación!F17,"") | G17: =IF(Navegación!G17<>"",Navegación!G17,"") | H17: =IF(Navegación!H17<>"",Navegación!H17,"") | I17: =IF(Navegación!I17<>"",Navegación!I17,"")
B18: Fecha inicio contrato: | D18: =IF(Navegación!D18<>"",Navegación!D18,"") -> 45849 | E18: =IF(Navegación!E18<>"",Navegación!E18,"") | F18: =IF(Navegación!F18<>"",Navegación!F18,"") | G18: =IF(Navegación!G18<>"",Navegación!G18,"") | H18: =IF(Navegación!H18<>"",Navegación!H18,"") | I18: =IF(Navegación!I18<>"",Navegación!I18,"")
B19: Fecha finalización contrato: (Si es indefinido escribir 31/12/9999) | D19: =IF(Navegación!D19<>"",Navegación!D19,"") | E19: =IF(Navegación!E19<>"",Navegación!E19,"") | F19: =IF(Navegación!F19<>"",Navegación!F19,"") | G19: =IF(Navegación!G19<>"",Navegación!G19,"") | H19: =IF(Navegación!H19<>"",Navegación!H19,"") | I19: =IF(Navegación!I19<>"",Navegación!I19,"")
B21: Requerimientos Share Point | D21: =IF(DZ22>0,Navegación!$E$22,"") -> Esta aplicación solo requiere VoBo de su Jefatura
B22: Novedad Windows (Crear/Modificar/Baja) | D22: Crear | DZ22: =COUNTIF(D22:I22,"<>") -> 1
B23: Alias del Usuario Windows
B24: URL | D24: https://cafamonline.sharepoint.com/sites/Sub_TID/Gestion%20de%20proyectos%20TI/Formatos%20Base/Forms/AllItems.aspx?id=%2Fsites%2FSub%5FTID%2FGestion%20de%20proyectos%20TI%2FFormatos%20Base%2FBuenas%20practicas%20Desarrollo%20%20Gobierno%20TI&viewid=12aefa60%2D5848%2D4042%2D8abb%2D1af8493c56f2
B25: Biblioteca
B26: Tipo permiso | D26: Lectura
B28: Observaciones | C28: Grupo de recursos por suscripción: az-trv-prod-suscripcion - az-trv-prd-rg-apim az-hub-devqa-suscripcion - az-hub-devqa-rg-security-00
B33: ='WINDOWS 1'!$B$37 -> APROBADOR POR: Jefe Dpto. Servicios Compartidos | F33: ='WINDOWS 1'!F37 -> V20 de 26/09/2023 | I33: ="Pág. " &Navegación!B22 & " de " &Navegación!$B$102 -> Pág. 2 de 54
DZ37: =COUNTIF(D22:I22,"<>") -> 1
DZ44: =COUNTIF(#REF!,"<>") -> #REF!
DZ47: =COUNTIF(#REF!,"<>") -> #REF!

Sheet WINDOWS 3
K1: 2958465
C2: FORMATO: GESTIÓN DE IDENTIDADES
F3: DOCUMENTO USO INTERNO
B5: Las celdas resaltadas en Naranja son campos obligatorios del Formato.
B6: Información Usuarios | D6: Usuario 1 | E6: Usuario 2 | F6: Usuario 3 | G6: Usuario 4 | H6: Usuario 5 | I6: Usuario 6
B7: Tipo de documento | D7: =IF(Navegación!D7<>"",Navegación!D7,"") -> Cédula Ciudadanía | E7: =IF(Navegación!E7<>"",Navegación!E7,"") | F7: =IF(Navegación!F7<>"",Navegación!F7,"") | G7: =IF(Navegación!G7<>"",Navegación!G7,"") | H7: =IF(Navegación!H7<>"",Navegación!H7,"") | I7: =IF(Navegación!I7<>"",Navegación!I7,"")
B8: Identificación | D8: =IF(Navegación!D8<>"",Navegación!D8,"") -> 1001089595 | E8: =IF(Navegación!E8<>"",Navegación!E8,"") | F8: =IF(Navegación!F8<>"",Navegación!F8,"") | G8: =IF(Navegación!G8<>"",Navegación!G8,"") | H8: =IF(Navegación!H8<>"",Navegación!H8,"") | I8: =IF(Navegación!I8<>"",Navegación!I8,"")
B9: Nombres completos | D9: =IF(Navegación!D9<>"",Navegación!D9,"") -> JUAN PABLO | E9: =IF(Navegación!E9<>"",Navegación!E9,"") | F9: =IF(Navegación!F9<>"",Navegación!F9,"") | G9: =IF(Navegación!G9<>"",Navegación!G9,"") | H9: =IF(Navegación!H9<>"",Navegación!H9,"") | I9: =IF(Navegación!I9<>"",Navegación!I9,"")
B10: Apellidos completos | D10: =IF(Navegación!D10<>"",Navegación!D10,"") -> CAMPO TELLEZ | E10: =IF(Navegación!E10<>"",Navegación!E10,"") | F10: =IF(Navegación!F10<>"",Navegación!F10,"") | G10: =IF(Navegación!G10<>"",Navegación!G10,"") | H10: =IF(Navegación!H10<>"",Navegación!H10,"") | I10: =IF(Navegación!I10<>"",Navegación!I10,"")
B11: Centro de costo | D11: =IF(Navegación!D11<>"",Navegación!D11,"") -> 856 | E11: =IF(Navegación!E11<>"",Navegación!E11,"") | F11: =IF(Navegación!F11<>"",Navegación!F11,"") | G11: =IF(Navegación!G11<>"",Navegación!G11,"") | H11: =IF(Navegación!H11<>"",Navegación!H11,"") | I11: =IF(Navegación!I11<>"",Navegación!I11,"")
B12: Teléfono/Extensión de contacto del usuario | D12: =IF(Navegación!D12<>"",Navegación!D12,"") | E12: =IF(Navegación!E12<>"",Navegación!E12,"") | F12: =IF(Navegación!F12<>"",Navegación!F12,"") | G12: =IF(Navegación!G12<>"",Navegación!G12,"") | H12: =IF(Navegación!H12<>"",Navegación!H12,"") | I12: =IF(Navegación!I12<>"",Navegación!I12,"")
B13: Celular | D13: =IF(Navegación!D13<>"",Navegación!D13,"") -> 3150727969 | E13: =IF(Navegación!E13<>"",Navegación!E13,"") | F13: =IF(Navegación!F13<>"",Navegación!F13,"") | G13: =IF(Navegación!G13<>"",Navegación!G13,"") | H13: =IF(Navegación!H13<>"",Navegación!H13,"") | I13: =IF(Navegación!I13<>"",Navegación!I13,"")
B14: Dependencia | D14: =IF(Navegación!D14<>"",Navegación!D14,"") -> Gobierno | E14: =IF(Navegación!E14<>"",Navegación!E14,"") | F14: =IF(Navegación!F14<>"",Navegación!F14,"") | G14: =IF(Navegación!G14<>"",Navegación!G14,"") | H14: =IF(Navegación!H14<>"",Navegación!H14,"") | I14: =IF(Navegación!I14<>"",Navegación!I14,"")
B15: Cargo | D15: =IF(Navegación!D15<>"",Navegación!D15,"") -> Aprendiz Universitario | E15: =IF(Navegación!E15<>"",Navegación!E15,"") | F15: =IF(Navegación!F15<>"",Navegación!F15,"") | G15: =IF(Navegación!G15<>"",Navegación!G15,"") | H15: =IF(Navegación!H15<>"",Navegación!H15,"") | I15: =IF(Navegación!I15<>"",Navegación!I15,"")
B16: Empleado Cafam o Externo | D16: =IF(Navegación!D16<>"",Navegación!D16,"") -> Empleado CAFAM | E16: =IF(Navegación!E16<>"",Navegación!E16,"") | F16: =IF(Navegación!F16<>"",Navegación!F16,"") | G16: =IF(Navegación!G16<>"",Navegación!G16,"") | H16: =IF(Navegación!H16<>"",Navegación!H16,"") | I16: =IF(Navegación!I16<>"",Navegación!I16,"")
B17: Nombre de la empresa cuando es Externo | D17: =IF(Navegación!D17<>"",Navegación!D17,"") | E17: =IF(Navegación!E17<>"",Navegación!E17,"") | F17: =IF(Navegación!F17<>"",Navegación!F17,"") | G17: =IF(Navegación!G17<>"",Navegación!G17,"") | H17: =IF(Navegación!H17<>"",Navegación!H17,"") | I17: =IF(Navegación!I17<>"",Navegación!I17,"")
B18: Fecha inicio contrato: | D18: =IF(Navegación!D18<>"",Navegación!D18,"") -> 45849 | E18: =IF(Navegación!E18<>"",Navegación!E18,"") | F18: =IF(Navegación!F18<>"",Navegación!F18,"") | G18: =IF(Navegación!G18<>"",Navegación!G18,"") | H18: =IF(Navegación!H18<>"",Navegación!H18,"") | I18: =IF(Navegación!I18<>"",Navegación!I18,"")
B19: Fecha finalización contrato: (Si es indefinido escribir 31/12/9999) | D19: =IF(Navegación!D19<>"",Navegación!D19,"") | E19: =IF(Navegación!E19<>"",Navegación!E19,"") | F19: =IF(Navegación!F19<>"",Navegación!F19,"") | G19: =IF(Navegación!G19<>"",Navegación!G19,"") | H19: =IF(Navegación!H19<>"",Navegación!H19,"") | I19: =IF(Navegación!I19<>"",Navegación!I19,"")
B21: Requerimientos Office 365 | D21: =IF(OR(DZ23>0,DZ26>0),Navegación!$E$23,"")
B22: Sr. Usuario. Tenga en cuenta que la asignación de Licencia Office 365 puede acarrear costos adicionales para su CeCo. Si se trata de un reemplazo, indique el nombre de la persona que esta reemplazando, de lo contrario confirme con su jefatura la disponibilidad de licencia.
B23: Buzón de correo personal (Crear/Modificar/Baja) | DZ23: =COUNTIF(D23:I23,"<>") -> 0
B24: Tipo Licencia Office 365
B25: Nombre del buzón a modificar o dar de baja
B26: Buzón de correo del área (Crear/Modificar/Baja) | DZ26: =COUNTIF(D26:I26,"<>") -> 0
B27: Detalle del buzón de correo del área
B28: Power BI-Pro | DZ28: =COUNTIF(D28:I28,"<>") -> 0
B29: Generar Backup de la cuenta Office? | C29: Cuenta Origen | DZ29: =COUNTIF(D29:I30,"<>") -> 0
C30: Cuenta Destino
B32: Observaciones
B37: ='WINDOWS 1'!$B$37 -> APROBADOR POR: Jefe Dpto. Servicios Compartidos | F37: ='WINDOWS 1'!F37 -> V20 de 26/09/2023 | I37: ="Pág. " &Navegación!B23 & " de " &Navegación!$B$102 -> Pág. 3 de 54
DZ44: =COUNTIF(D23:I23,"<>") -> 0
DZ47: =COUNTIF(D26:I26,"<>") -> 0

Sheet SALUD 1
K1: 2958465
C2: FORMATO: GESTIÓN DE IDENTIDADES
F3: DOCUMENTO USO INTERNO
B5: Las celdas resaltadas en Naranja son campos obligatorios del Formato.
B6: Información Usuarios | D6: Usuario 1 | E6: Usuario 2 | F6: Usuario 3 | G6: Usuario 4 | H6: Usuario 5 | I6: Usuario 6
B7: Tipo de documento | D7: =IF(Navegación!D7<>"",Navegación!D7,"") -> Cédula Ciudadanía | E7: =IF(Navegación!E7<>"",Navegación!E7,"") | F7: =IF(Navegación!F7<>"",Navegación!F7,"") | G7: =IF(Navegación!G7<>"",Navegación!G7,"") | H7: =IF(Navegación!H7<>"",Navegación!H7,"") | I7: =IF(Navegación!I7<>"",Navegación!I7,"")
B8: Identificación | D8: =IF(Navegación!D8<>"",Navegación!D8,"") -> 1001089595 | E8: =IF(Navegación!E8<>"",Navegación!E8,"") | F8: =IF(Navegación!F8<>"",Navegación!F8,"") | G8: =IF(Navegación!G8<>"",Navegación!G8,"") | H8: =IF(Navegación!H8<>"",Navegación!H8,"") | I8: =IF(Navegación!I8<>"",Navegación!I8,"")
B9: Nombres completos | D9: =IF(Navegación!D9<>"",Navegación!D9,"") -> JUAN PABLO | E9: =IF(Navegación!E9<>"",Navegación!E9,"") | F9: =IF(Navegación!F9<>"",Navegación!F9,"") | G9: =IF(Navegación!G9<>"",Navegación!G9,"") | H9: =IF(Navegación!H9<>"",Navegación!H9,"") | I9: =IF(Navegación!I9<>"",Navegación!I9,"")
B10: Apellidos completos | D10: =IF(Navegación!D10<>"",Navegación!D10,"") -> CAMPO TELLEZ | E10: =IF(Navegación!E10<>"",Navegación!E10,"") | F10: =IF(Navegación!F10<>"",Navegación!F10,"") | G10: =IF(Navegación!G10<>"",Navegación!G10,"") | H10: =IF(Navegación!H10<>"",Navegación!H10,"") | I10: =IF(Navegación!I10<>"",Navegación!I10,"")
B11: Centro de costo | D11: =IF(Navegación!D11<>"",Navegación!D11,"") -> 856 | E11: =IF(Navegación!E11<>"",Navegación!E11,"") | F11: =IF(Navegación!F11<>"",Navegación!F11,"") | G11: =IF(Navegación!G11<>"",Navegación!G11,"") | H11: =IF(Navegación!H11<>"",Navegación!H11,"") | I11: =IF(Navegación!I11<>"",Navegación!I11,"")
B12: Teléfono/Extensión de contacto del usuario | D12: =IF(Navegación!D12<>"",Navegación!D12,"") | E12: =IF(Navegación!E12<>"",Navegación!E12,"") | F12: =IF(Navegación!F12<>"",Navegación!F12,"") | G12: =IF(Navegación!G12<>"",Navegación!G12,"") | H12: =IF(Navegación!H12<>"",Navegación!H12,"") | I12: =IF(Navegación!I12<>"",Navegación!I12,"")
B13: Celular | D13: =IF(Navegación!D13<>"",Navegación!D13,"") -> 3150727969 | E13: =IF(Navegación!E13<>"",Navegación!E13,"") | F13: =IF(Navegación!F13<>"",Navegación!F13,"") | G13: =IF(Navegación!G13<>"",Navegación!G13,"") | H13: =IF(Navegación!H13<>"",Navegación!H13,"") | I13: =IF(Navegación!I13<>"",Navegación!I13,"")
B14: Dependencia | D14: =IF(Navegación!D14<>"",Navegación!D14,"") -> Gobierno | E14: =IF(Navegación!E14<>"",Navegación!E14,"") | F14: =IF(Navegación!F14<>"",Navegación!F14,"") | G14: =IF(Navegación!G14<>"",Navegación!G14,"") | H14: =IF(Navegación!H14<>"",Navegación!H14,"") | I14: =IF(Navegación!I14<>"",Navegación!I14,"")
B15: Cargo | D15: =IF(Navegación!D15<>"",Navegación!D15,"") -> Aprendiz Universitario | E15: =IF(Navegación!E15<>"",Navegación!E15,"") | F15: =IF(Navegación!F15<>"",Navegación!F15,"") | G15: =IF(Navegación!G15<>"",Navegación!G15,"") | H15: =IF(Navegación!H15<>"",Navegación!H15,"") | I15: =IF(Navegación!I15<>"",Navegación!I15,"")
B16: Empleado Cafam o Externo | D16: =IF(Navegación!D16<>"",Navegación!D16,"") -> Empleado CAFAM | E16: =IF(Navegación!E16<>"",Navegación!E16,"") | F16: =IF(Navegación!F16<>"",Navegación!F16,"") | G16: =IF(Navegación!G16<>"",Navegación!G16,"") | H16: =IF(Navegación!H16<>"",Navegación!H16,"") | I16: =IF(Navegación!I16<>"",Navegación!I16,"")
B17: Nombre de la empresa cuando es Externo | D17: =IF(Navegación!D17<>"",Navegación!D17,"") | E17: =IF(Navegación!E17<>"",Navegación!E17,"") | F17: =IF(Navegación!F17<>"",Navegación!F17,"") | G17: =IF(Navegación!G17<>"",Navegación!G17,"") | H17: =IF(Navegación!H17<>"",Navegación!H17,"") | I17: =IF(Navegación!I17<>"",Navegación!I17,"")
B18: Fecha inicio contrato: | D18: =IF(Navegación!D18<>"",Navegación!D18,"") -> 45849 | E18: =IF(Navegación!E18<>"",Navegación!E18,"") | F18: =IF(Navegación!F18<>"",Navegación!F18,"") | G18: =IF(Navegación!G18<>"",Navegación!G18,"") | H18: =IF(Navegación!H18<>"",Navegación!H18,"") | I18: =IF(Navegación!I18<>"",Navegación!I18,"")
B19: Fecha finalización contrato: (Si es indefinido escribir 31.12.9999) | D19: =IF(Navegación!D19<>"",Navegación!D19,"") | E19: =IF(Navegación!E19<>"",Navegación!E19,"") | F19: =IF(Navegación!F19<>"",Navegación!F19,"") | G19: =IF(Navegación!G19<>"",Navegación!G19,"") | H19: =IF(Navegación!H19<>"",Navegación!H19,"") | I19: =IF(Navegación!I19<>"",Navegación!I19,"")
B21: PANA - FAMISANAR | D21: =IF(DZ26>0,Navegación!$E$26,"")
D22: =ADDRESS(MATCH(D$28,SaludSedes1[[#All],[EPS]],0)+252,13,1) -> $M$254 | E22: =ADDRESS(MATCH(E$28,SaludSedes1[[#All],[EPS]],0)+252,13,1) -> $M$254 | F22: =ADDRESS(MATCH(F$28,SaludSedes1[[#All],[EPS]],0)+252,13,1) -> $M$254 | G22: =ADDRESS(MATCH(G$28,SaludSedes1[[#All],[EPS]],0)+252,13,1) -> $M$254 | H22: =ADDRESS(MATCH(H$28,SaludSedes1[[#All],[EPS]],0)+252,13,1) -> $M$254 | I22: =ADDRESS(MATCH(I$28,SaludSedes1[[#All],[EPS]],0)+252,13,1) -> $M$254
D23: =ADDRESS(MATCH(D$28,SaludTipoPerfil1[[#All],[Aplicacion]],0)+252,16,1) -> $P$254 | E23: =ADDRESS(MATCH(E$28,SaludTipoPerfil1[[#All],[Aplicacion]],0)+252,16,1) -> $P$254 | F23: =ADDRESS(MATCH(F$28,SaludTipoPerfil1[[#All],[Aplicacion]],0)+252,16,1) -> $P$254 | G23: =ADDRESS(MATCH(G$28,SaludTipoPerfil1[[#All],[Aplicacion]],0)+252,16,1) -> $P$254 | H23: =ADDRESS(MATCH(H$28,SaludTipoPerfil1[[#All],[Aplicacion]],0)+252,16,1) -> $P$254 | I23: =ADDRESS(MATCH(I$28,SaludTipoPerfil1[[#All],[Aplicacion]],0)+252,16,1) -> $P$254
D24: =ADDRESS(MATCH(D$27,SaludPerfiles1[[#All],[TipoPerfil]],0)+251,20,1) -> #N/A | E24: =ADDRESS(MATCH(E$27,SaludPerfiles1[[#All],[TipoPerfil]],0)+251,20,1) -> #N/A | F24: =ADDRESS(MATCH(F$27,SaludPerfiles1[[#All],[TipoPerfil]],0)+251,20,1) -> #N/A | G24: =ADDRESS(MATCH(G$27,SaludPerfiles1[[#All],[TipoPerfil]],0)+251,20,1) -> #N/A | H24: =ADDRESS(MATCH(H$27,SaludPerfiles1[[#All],[TipoPerfil]],0)+251,20,1) -> #N/A | I24: =ADDRESS(MATCH(I$27,SaludPerfiles1[[#All],[TipoPerfil]],0)+251,20,1) -> #N/A
D25: =ADDRESS(MATCH(D$28&" "&D$32,SaludEspecialidades1[[#All],[Sistema]],0)+251,23,1) -> #N/A | E25: =ADDRESS(MATCH(E$28&" "&E$32,SaludEspecialidades1[[#All],[Sistema]],0)+251,23,1) -> #N/A | F25: =ADDRESS(MATCH(F$28&" "&F$32,SaludEspecialidades1[[#All],[Sistema]],0)+251,23,1) -> #N/A | G25: =ADDRESS(MATCH(G$28&" "&G$32,SaludEspecialidades1[[#All],[Sistema]],0)+251,23,1) -> #N/A | H25: =ADDRESS(MATCH(H$28&" "&H$32,SaludEspecialidades1[[#All],[Sistema]],0)+251,23,1) -> #N/A | I25: =ADDRESS(MATCH(I$28&" "&I$32,SaludEspecialidades1[[#All],[Sistema]],0)+251,23,1) -> #N/A
B26: Novedad (Crear/Inactivar): | DZ26: =COUNTIF(D26:I26,"<>") -> 0
B27: Tipo de Perfil
B28: EPS | D28: PANA-FAMISANAR | E28: PANA-FAMISANAR | F28: PANA-FAMISANAR | G28: PANA-FAMISANAR | H28: PANA-FAMISANAR | I28: PANA-FAMISANAR
B29: Sede
B30: Alias usuario
B31: Registro profesional
B32: Perfil
B33: Especialidad
B34: Dirección
B35: Celular/Telefono
B36: Información RETHUS
B37: Tipo Programa
B38: Origen Obtención
B39: Titulo Profesional
B40: Entidad Reportadora
B41: Fecha consulta RETHUS
DZ42: =COUNTIF(#REF!,"<>") -> #REF!
...

Sheet SALUD 2
K1: 2958465
C2: FORMATO: GESTIÓN DE IDENTIDADES
F3: DOCUMENTO USO INTERNO
B5: Las celdas resaltadas en Naranja son campos obligatorios del Formato.
B6: Información Usuarios | D6: Usuario 1 | E6: Usuario 2 | F6: Usuario 3 | G6: Usuario 4 | H6: Usuario 5 | I6: Usuario 6
B7: Tipo de documento | D7: =IF(Navegación!D7<>"",Navegación!D7,"") -> Cédula Ciudadanía | E7: =IF(Navegación!E7<>"",Navegación!E7,"") | F7: =IF(Navegación!F7<>"",Navegación!F7,"") | G7: =IF(Navegación!G7<>"",Navegación!G7,"") | H7: =IF(Navegación!H7<>"",Navegación!H7,"") | I7: =IF(Navegación!I7<>"",Navegación!I7,"")
B8: Identificación | D8: =IF(Navegación!D8<>"",Navegación!D8,"") -> 1001089595 | E8: =IF(Navegación!E8<>"",Navegación!E8,"") | F8: =IF(Navegación!F8<>"",Navegación!F8,"") | G8: =IF(Navegación!G8<>"",Navegación!G8,"") | H8: =IF(Navegación!H8<>"",Navegación!H8,"") | I8: =IF(Navegación!I8<>"",Navegación!I8,"")
B9: Nombres completos | D9: =IF(Navegación!D9<>"",Navegación!D9,"") -> JUAN PABLO | E9: =IF(Navegación!E9<>"",Navegación!E9,"") | F9: =IF(Navegación!F9<>"",Navegación!F9,"") | G9: =IF(Navegación!G9<>"",Navegación!G9,"") | H9: =IF(Navegación!H9<>"",Navegación!H9,"") | I9: =IF(Navegación!I9<>"",Navegación!I9,"")
B10: Apellidos completos | D10: =IF(Navegación!D10<>"",Navegación!D10,"") -> CAMPO TELLEZ | E10: =IF(Navegación!E10<>"",Navegación!E10,"") | F10: =IF(Navegación!F10<>"",Navegación!F10,"") | G10: =IF(Navegación!G10<>"",Navegación!G10,"") | H10: =IF(Navegación!H10<>"",Navegación!H10,"") | I10: =IF(Navegación!I10<>"",Navegación!I10,"")
B11: Centro de costo | D11: =IF(Navegación!D11<>"",Navegación!D11,"") -> 856 | E11: =IF(Navegación!E11<>"",Navegación!E11,"") | F11: =IF(Navegación!F11<>"",Navegación!F11,"") | G11: =IF(Navegación!G11<>"",Navegación!G11,"") | H11: =IF(Navegación!H11<>"",Navegación!H11,"") | I11: =IF(Navegación!I11<>"",Navegación!I11,"")
B12: Teléfono/Extensión de contacto del usuario | D12: =IF(Navegación!D12<>"",Navegación!D12,"") | E12: =IF(Navegación!E12<>"",Navegación!E12,"") | F12: =IF(Navegación!F12<>"",Navegación!F12,"") | G12: =IF(Navegación!G12<>"",Navegación!G12,"") | H12: =IF(Navegación!H12<>"",Navegación!H12,"") | I12: =IF(Navegación!I12<>"",Navegación!I12,"")
B13: Celular | D13: =IF(Navegación!D13<>"",Navegación!D13,"") -> 3150727969 | E13: =IF(Navegación!E13<>"",Navegación!E13,"") | F13: =IF(Navegación!F13<>"",Navegación!F13,"") | G13: =IF(Navegación!G13<>"",Navegación!G13,"") | H13: =IF(Navegación!H13<>"",Navegación!H13,"") | I13: =IF(Navegación!I13<>"",Navegación!I13,"")
B14: Dependencia | D14: =IF(Navegación!D14<>"",Navegación!D14,"") -> Gobierno | E14: =IF(Navegación!E14<>"",Navegación!E14,"") | F14: =IF(Navegación!F14<>"",Navegación!F14,"") | G14: =IF(Navegación!G14<>"",Navegación!G14,"") | H14: =IF(Navegación!H14<>"",Navegación!H14,"") | I14: =IF(Navegación!I14<>"",Navegación!I14,"")
B15: Cargo | D15: =IF(Navegación!D15<>"",Navegación!D15,"") -> Aprendiz Universitario | E15: =IF(Navegación!E15<>"",Navegación!E15,"") | F15: =IF(Navegación!F15<>"",Navegación!F15,"") | G15: =IF(Navegación!G15<>"",Navegación!G15,"") | H15: =IF(Navegación!H15<>"",Navegación!H15,"") | I15: =IF(Navegación!I15<>"",Navegación!I15,"")
B16: Empleado Cafam o Externo | D16: =IF(Navegación!D16<>"",Navegación!D16,"") -> Empleado CAFAM | E16: =IF(Navegación!E16<>"",Navegación!E16,"") | F16: =IF(Navegación!F16<>"",Navegación!F16,"") | G16: =IF(Navegación!G16<>"",Navegación!G16,"") | H16: =IF(Navegación!H16<>"",Navegación!H16,"") | I16: =IF(Navegación!I16<>"",Navegación!I16,"")
B17: Nombre de la empresa cuando es Externo | D17: =IF(Navegación!D17<>"",Navegación!D17,"") | E17: =IF(Navegación!E17<>"",Navegación!E17,"") | F17: =IF(Navegación!F17<>"",Navegación!F17,"") | G17: =IF(Navegación!G17<>"",Navegación!G17,"") | H17: =IF(Navegación!H17<>"",Navegación!H17,"") | I17: =IF(Navegación!I17<>"",Navegación!I17,"")
B18: Fecha inicio contrato: | D18: =IF(Navegación!D18<>"",Navegación!D18,"") -> 45849 | E18: =IF(Navegación!E18<>"",Navegación!E18,"") | F18: =IF(Navegación!F18<>"",Navegación!F18,"") | G18: =IF(Navegación!G18<>"",Navegación!G18,"") | H18: =IF(Navegación!H18<>"",Navegación!H18,"") | I18: =IF(Navegación!I18<>"",Navegación!I18,"")
B19: Fecha finalización contrato: (Si es indefinido escribir 31.12.9999) | D19: =IF(Navegación!D19<>"",Navegación!D19,"") | E19: =IF(Navegación!E19<>"",Navegación!E19,"") | F19: =IF(Navegación!F19<>"",Navegación!F19,"") | G19: =IF(Navegación!G19<>"",Navegación!G19,"") | H19: =IF(Navegación!H19<>"",Navegación!H19,"") | I19: =IF(Navegación!I19<>"",Navegación!I19,"")
B21: PANA - NEPS | D21: =IF(DZ25>0,Navegación!$E$27,"")
D22: =ADDRESS(MATCH(D$28,SaludSedes2[[#All],[EPS]],0)+252,13,1) -> #N/A | E22: =ADDRESS(MATCH(E$28,SaludSedes2[[#All],[EPS]],0)+252,13,1) -> #N/A | F22: =ADDRESS(MATCH(F$28,SaludSedes2[[#All],[EPS]],0)+252,13,1) -> #N/A | G22: =ADDRESS(MATCH(G$28,SaludSedes2[[#All],[EPS]],0)+252,13,1) -> #N/A | H22: =ADDRESS(MATCH(H$28,SaludSedes2[[#All],[EPS]],0)+252,13,1) -> #N/A | I22: =ADDRESS(MATCH(I$28,SaludSedes2[[#All],[EPS]],0)+252,13,1) -> #N/A
D23: =ADDRESS(MATCH(D$28,SaludTipoPerfil2[[#All],[Aplicacion]],0)+252,16,1) -> #N/A | E23: =ADDRESS(MATCH(E$28,SaludTipoPerfil2[[#All],[Aplicacion]],0)+252,16,1) -> #N/A | F23: =ADDRESS(MATCH(F$28,SaludTipoPerfil2[[#All],[Aplicacion]],0)+252,16,1) -> #N/A | G23: =ADDRESS(MATCH(G$28,SaludTipoPerfil2[[#All],[Aplicacion]],0)+252,16,1) -> #N/A | H23: =ADDRESS(MATCH(H$28,SaludTipoPerfil2[[#All],[Aplicacion]],0)+252,16,1) -> #N/A | I23: =ADDRESS(MATCH(I$28,SaludTipoPerfil2[[#All],[Aplicacion]],0)+252,16,1) -> #N/A
D24: =ADDRESS(MATCH(D$27,SaludPerfiles2[[#All],[TipoPerfil]],0)+251,20,1) -> #N/A | E24: =ADDRESS(MATCH(E$27,SaludPerfiles2[[#All],[TipoPerfil]],0)+251,20,1) -> #N/A | F24: =ADDRESS(MATCH(F$27,SaludPerfiles2[[#All],[TipoPerfil]],0)+251,20,1) -> #N/A | G24: =ADDRESS(MATCH(G$27,SaludPerfiles2[[#All],[TipoPerfil]],0)+251,20,1) -> #N/A | H24: =ADDRESS(MATCH(H$27,SaludPerfiles2[[#All],[TipoPerfil]],0)+251,20,1) -> #N/A | I24: =ADDRESS(MATCH(I$27,SaludPerfiles2[[#All],[TipoPerfil]],0)+251,20,1) -> #N/A
D25: =ADDRESS(MATCH(D$28&" "&D$32,SaludEspecialidades2[[#All],[Sistema]],0)+251,23,1) -> #N/A | E25: =ADDRESS(MATCH(E$28&" "&E$32,SaludEspecialidades2[[#All],[Sistema]],0)+251,23,1) -> #N/A | F25: =ADDRESS(MATCH(F$28&" "&F$32,SaludEspecialidades2[[#All],[Sistema]],0)+251,23,1) -> #N/A | G25: =ADDRESS(MATCH(G$28&" "&G$32,SaludEspecialidades2[[#All],[Sistema]],0)+251,23,1) -> #N/A | H25: =ADDRESS(MATCH(H$28&" "&H$32,SaludEspecialidades2[[#All],[Sistema]],0)+251,23,1) -> #N/A | I25: =ADDRESS(MATCH(I$28&" "&I$32,SaludEspecialidades2[[#All],[Sistema]],0)+251,23,1) -> #N/A | DZ25: =COUNTIF(D26:I26,"<>") -> 0
B26: Novedad (Crear/Inactivar): | DZ26: =COUNTIF(#REF!,"<>") -> #REF!
B27: Tipo de Perfil
B28: EPS
B29: Sede
B30: Alias usuario
B31: Registro profesional
B32: Perfil
B33: Especialidad
B34: Información RETHUS
B35: Tipo Programa
B36: Origen Obtención
B37: Titulo Profesional
B38: Entidad Reportadora
... B41: Observaciones
B46: ='WINDOWS 1'!$B$37 -> APROBADOR POR: Jefe Dpto. Servicios Compartidos | F46: ='WINDOWS 1'!F37 -> V20 de 26/09/2023 | I46: ="Pág. " &Navegación!B27 & " de " &Navegación!$B$102 -> Pág. 5 de 54
DZ51: =COUNTIF(D35:I35,"<>") -> 0
DZ58: =COUNTIF(#REF!,"<>") -> #REF!
...

Sheet SALUD 3
K1: 2958465
C2: FORMATO: GESTIÓN DE IDENTIDADES
F3: DOCUMENTO USO INTERNO
B5: Las celdas resaltadas en Naranja son campos obligatorios del Formato.
B6: Información Usuarios | D6: Usuario 1 | E6: Usuario 2 | F6: Usuario 3 | G6: Usuario 4 | H6: Usuario 5 | I6: Usuario 6
B7: Tipo de documento | D7: =IF(Navegación!D7<>"",Navegación!D7,"") -> Cédula Ciudadanía | E7: =IF(Navegación!E7<>"",Navegación!E7,"") | F7: =IF(Navegación!F7<>"",Navegación!F7,"") | G7: =IF(Navegación!G7<>"",Navegación!G7,"") | H7: =IF(Navegación!H7<>"",Navegación!H7,"") | I7: =IF(Navegación!I7<>"",Navegación!I7,"")
B8: Identificación | D8: =IF(Navegación!D8<>"",Navegación!D8,"") -> 1001089595 | E8: =IF(Navegación!E8<>"",Navegación!E8,"") | F8: =IF(Navegación!F8<>"",Navegación!F8,"") | G8: =IF(Navegación!G8<>"",Navegación!G8,"") | H8: =IF(Navegación!H8<>"",Navegación!H8,"") | I8: =IF(Navegación!I8<>"",Navegación!I8,"")
B9: Nombres completos | D9: =IF(Navegación!D9<>"",Navegación!D9,"") -> JUAN PABLO | E9: =IF(Navegación!E9<>"",Navegación!E9,"") | F9: =IF(Navegación!F9<>"",Navegación!F9,"") | G9: =IF(Navegación!G9<>"",Navegación!G9,"") | H9: =IF(Navegación!H9<>"",Navegación!H9,"") | I9: =IF(Navegación!I9<>"",Navegación!I9,"")
B10: Apellidos completos | D10: =IF(Navegación!D10<>"",Navegación!D10,"") -> CAMPO TELLEZ | E10: =IF(Navegación!E10<>"",Navegación!E10,"") | F10: =IF(Navegación!F10<>"",Navegación!F10,"") | G10: =IF(Navegación!G10<>"",Navegación!G10,"") | H10: =IF(Navegación!H10<>"",Navegación!H10,"") | I10: =IF(Navegación!I10<>"",Navegación!I10,"")
B11: Centro de costo | D11: =IF(Navegación!D11<>"",Navegación!D11,"") -> 856 | E11: =IF(Navegación!E11<>"",Navegación!E11,"") | F11: =IF(Navegación!F11<>"",Navegación!F11,"") | G11: =IF(Navegación!G11<>"",Navegación!G11,"") | H11: =IF(Navegación!H11<>"",Navegación!H11,"") | I11: =IF(Navegación!I11<>"",Navegación!I11,"")
B12: Teléfono/Extensión de contacto del usuario | D12: =IF(Navegación!D12<>"",Navegación!D12,"") | E12: =IF(Navegación!E12<>"",Navegación!E12,"") | F12: =IF(Navegación!F12<>"",Navegación!F12,"") | G12: =IF(Navegación!G12<>"",Navegación!G12,"") | H12: =IF(Navegación!H12<>"",Navegación!H12,"") | I12: =IF(Navegación!I12<>"",Navegación!I12,"")
B13: Celular | D13: =IF(Navegación!D13<>"",Navegación!D13,"") -> 3150727969 | E13: =IF(Navegación!E13<>"",Navegación!E13,"") | F13: =IF(Navegación!F13<>"",Navegación!F13,"") | G13: =IF(Navegación!G13<>"",Navegación!G13,"") | H13: =IF(Navegación!H13<>"",Navegación!H13,"") | I13: =IF(Navegación!I13<>"",Navegación!I13,"")
B14: Dependencia | D14: =IF(Navegación!D14<>"",Navegación!D14,"") -> Gobierno | E14: =IF(Navegación!E14<>"",Navegación!E14,"") | F14: =IF(Navegación!F14<>"",Navegación!F14,"") | G14: =IF(Navegación!G14<>"",Navegación!G14,"") | H14: =IF(Navegación!H14<>"",Navegación!H14,"") | I14: =IF(Navegación!I14<>"",Navegación!I14,"")
B15: Cargo | D15: =IF(Navegación!D15<>"",Navegación!D15,"") -> Aprendiz Universitario | E15: =IF(Navegación!E15<>"",Navegación!E15,"") | F15: =IF(Navegación!F15<>"",Navegación!F15,"") | G15: =IF(Navegación!G15<>"",Navegación!G15,"") | H15: =IF(Navegación!H15<>"",Navegación!H15,"") | I15: =IF(Navegación!I15<>"",Navegación!I15,"")
B16: Empleado Cafam o Externo | D16: =IF(Navegación!D16<>"",Navegación!D16,"") -> Empleado CAFAM | E16: =IF(Navegación!E16<>"",Navegación!E16,"") | F16: =IF(Navegación!F16<>"",Navegación!F16,"") | G16: =IF(Navegación!G16<>"",Navegación!G16,"") | H16: =IF(Navegación!H16<>"",Navegación!H16,"") | I16: =IF(Navegación!I16<>"",Navegación!I16,"")
B17: Nombre de la empresa cuando es Externo | D17: =IF(Navegación!D17<>"",Navegación!D17,"") | E17: =IF(Navegación!E17<>"",Navegación!E17,"") | F17: =IF(Navegación!F17<>"",Navegación!F17,"") | G17: =IF(Navegación!G17<>"",Navegación!G17,"") | H17: =IF(Navegación!H17<>"",Navegación!H17,"") | I17: =IF(Navegación!I17<>"",Navegación!I17,"")
B18: Fecha inicio contrato: | D18: =IF(Navegación!D18<>"",Navegación!D18,"") -> 45849 | E18: =IF(Navegación!E18<>"",Navegación!E18,"") | F18: =IF(Navegación!F18<>"",Navegación!F18,"") | G18: =IF(Navegación!G18<>"",Navegación!G18,"") | H18: =IF(Navegación!H18<>"",Navegación!H18,"") | I18: =IF(Navegación!I18<>"",Navegación!I18,"")
B19: Fecha finalización contrato: (Si es indefinido escribir 31.12.9999) | D19: =IF(Navegación!D19<>"",Navegación!D19,"") | E19: =IF(Navegación!E19<>"",Navegación!E19,"") | F19: =IF(Navegación!F19<>"",Navegación!F19,"") | G19: =IF(Navegación!G19<>"",Navegación!G19,"") | H19: =IF(Navegación!H19<>"",Navegación!H19,"") | I19: =IF(Navegación!I19<>"",Navegación!I19,"")
B20: ZERO | D20: =IF(DZ25>0,Navegación!$E$28,"")
D21: =ADDRESS(MATCH(D$24,SaluTipoPerfil7190[[#All],[Aplicacion]],0)+251,16,1) -> $P$253 | E21: =ADDRESS(MATCH(E$24,SaluTipoPerfil7190[[#All],[Aplicacion]],0)+251,16,1) -> $P$253 | F21: =ADDRESS(MATCH(F$24,SaluTipoPerfil7190[[#All],[Aplicacion]],0)+251,16,1) -> $P$253 | G21: =ADDRESS(MATCH(G$24,SaluTipoPerfil7190[[#All],[Aplicacion]],0)+251,16,1) -> $P$253 | H21: =ADDRESS(MATCH(H$24,SaluTipoPerfil7190[[#All],[Aplicacion]],0)+251,16,1) -> $P$253 | I21: =ADDRESS(MATCH(I$24,SaluTipoPerfil7190[[#All],[Aplicacion]],0)+251,16,1) -> $P$253
D22: =ADDRESS(MATCH(D$29,SaludPerfiles7291[[#All],[TipoPerfil]],0)+251,20,1) -> #N/A | E22: =ADDRESS(MATCH(E$29,SaludPerfiles7291[[#All],[TipoPerfil]],0)+251,20,1) -> #N/A | F22: =ADDRESS(MATCH(F$29,SaludPerfiles7291[[#All],[TipoPerfil]],0)+251,20,1) -> #N/A | G22: =ADDRESS(MATCH(G$29,SaludPerfiles7291[[#All],[TipoPerfil]],0)+251,20,1) -> #N/A | H22: =ADDRESS(MATCH(H$29,SaludPerfiles7291[[#All],[TipoPerfil]],0)+251,20,1) -> #N/A | I22: =ADDRESS(MATCH(I$29,SaludPerfiles7291[[#All],[TipoPerfil]],0)+251,20,1) -> #N/A
D23: =ADDRESS(MATCH(D$24,SaludEspecialidades3088[[#All],[Sistema]],0)+251,23,1) -> $W$253 | E23: =ADDRESS(MATCH(E$24,SaludEspecialidades3088[[#All],[Sistema]],0)+251,23,1) -> $W$253 | F23: =ADDRESS(MATCH(F$24,SaludEspecialidades3088[[#All],[Sistema]],0)+251,23,1) -> $W$253 | G23: =ADDRESS(MATCH(G$24,SaludEspecialidades3088[[#All],[Sistema]],0)+251,23,1) -> $W$253 | H23: =ADDRESS(MATCH(H$24,SaludEspecialidades3088[[#All],[Sistema]],0)+251,23,1) -> $W$253 | I23: =ADDRESS(MATCH(I$24,SaludEspecialidades3088[[#All],[Sistema]],0)+251,23,1) -> $W$253
B24: Aplicativo | D24: ZERO | E24: =D24 -> ZERO | F24: =E24 -> ZERO | G24: =F24 -> ZERO | H24: =G24 -> ZERO | I24: =H24 -> ZERO
B25: Novedad (Crear/Inactivar): | DZ25: =COUNTIF(D25:I25,"<>") -> 0
B26: Sede
B27: Alias usuario
B28: Registro profesional
B29: Tipo de Perfil | E29: =INDEX(SaludPerfiles7291[#All],MATCH(E$30,SaludPerfiles7291[[#All],[Perfil]],),MATCH(SaludPerfiles7291[[#Headers],[TipoPerfil]],SaludPerfiles7291[#Headers],)) -> #N/A | F29: =INDEX(SaludPerfiles7291[#All],MATCH(F$30,SaludPerfiles7291[[#All],[Perfil]],),MATCH(SaludPerfiles7291[[#Headers],[TipoPerfil]],SaludPerfiles7291[#Headers],)) -> #N/A | G29: =INDEX(SaludPerfiles7291[#All],MATCH(G$30,SaludPerfiles7291[[#All],[Perfil]],),MATCH(SaludPerfiles7291[[#Headers],[TipoPerfil]],SaludPerfiles7291[#Headers],)) -> #N/A | H29: =INDEX(SaludPerfiles7291[#All],MATCH(H$30,SaludPerfiles7291[[#All],[Perfil]],),MATCH(SaludPerfiles7291[[#Headers],[TipoPerfil]],SaludPerfiles7291[#Headers],)) -> #N/A | I29: =INDEX(SaludPerfiles7291[#All],MATCH(I$30,SaludPerfiles7291[[#All],[Perfil]],),MATCH(SaludPerfiles7291[[#Headers],[TipoPerfil]],SaludPerfiles7291[#Headers],)) -> #N/A
B30: Perfil
B31: Especialidad
B32: Deposito
B33: Requiere tarjeta/Devuelve tarjeta (Solo para inactivar) Recuerde devolver la tarjeta en caso de Inactivar usuario
B35: Observaciones
B40: ='WINDOWS 1'!$B$37 -> APROBADOR POR: Jefe Dpto. Servicios Compartidos | F40: ='WINDOWS 1'!F37 -> V20 de 26/09/2023 | I40: ="Pág. " &Navegación!B28 & " de " &Navegación!$B$102 -> Pág. 6 de 54
DZ42: =COUNTIF(#REF!,"<>") -> #REF!
DZ51: =COUNTIF(#REF!,"<>") -> #REF!
DZ58: =COUNTIF(#REF!,"<>") -> #REF!
DZ62: =COUNTIF(D25:I25,"<>") -> 0
DZ72: =COUNTIF(#REF!,"<>") -> #REF!
DZ82: =COUNTIF(#REF!,"<>") -> #REF!
...

Sheet SALUD 4
K1: 2958465
C2: FORMATO: GESTIÓN DE IDENTIDADES
F3: DOCUMENTO USO INTERNO
B5: Las celdas resaltadas en Naranja son campos obligatorios del Formato.
B6: Información Usuarios | D6: Usuario 1 | E6: Usuario 2 | F6: Usuario 3 | G6: Usuario 4 | H6: Usuario 5 | I6: Usuario 6
B7: Tipo de documento | D7: =IF(Navegación!D7<>"",Navegación!D7,"") -> Cédula Ciudadanía | E7: =IF(Navegación!E7<>"",Navegación!E7,"") | F7: =IF(Navegación!F7<>"",Navegación!F7,"") | G7: =IF(Navegación!G7<>"",Navegación!G7,"") | H7: =IF(Navegación!H7<>"",Navegación!H7,"") | I7: =IF(Navegación!I7<>"",Navegación!I7,"")
B8: Identificación | D8: =IF(Navegación!D8<>"",Navegación!D8,"") -> 1001089595 | E8: =IF(Navegación!E8<>"",Navegación!E8,"") | F8: =IF(Navegación!F8<>"",Navegación!F8,"") | G8: =IF(Navegación!G8<>"",Navegación!G8,"") | H8: =IF(Navegación!H8<>"",Navegación!H8,"") | I8: =IF(Navegación!I8<>"",Navegación!I8,"")
B9: Nombres completos | D9: =IF(Navegación!D9<>"",Navegación!D9,"") -> JUAN PABLO | E9: =IF(Navegación!E9<>"",Navegación!E9,"") | F9: =IF(Navegación!F9<>"",Navegación!F9,"") | G9: =IF(Navegación!G9<>"",Navegación!G9,"") | H9: =IF(Navegación!H9<>"",Navegación!H9,"") | I9: =IF(Navegación!I9<>"",Navegación!I9,"")
B10: Apellidos completos | D10: =IF(Navegación!D10<>"",Navegación!D10,"") -> CAMPO TELLEZ | E10: =IF(Navegación!E10<>"",Navegación!E10,"") | F10: =IF(Navegación!F10<>"",Navegación!F10,"") | G10: =IF(Navegación!G10<>"",Navegación!G10,"") | H10: =IF(Navegación!H10<>"",Navegación!H10,"") | I10: =IF(Navegación!I10<>"",Navegación!I10,"")
B11: Centro de costo | D11: =IF(Navegación!D11<>"",Navegación!D11,"") -> 856 | E11: =IF(Navegación!E11<>"",Navegación!E11,"") | F11: =IF(Navegación!F11<>"",Navegación!F11,"") | G11: =IF(Navegación!G11<>"",Navegación!G11,"") | H11: =IF(Navegación!H11<>"",Navegación!H11,"") | I11: =IF(Navegación!I11<>"",Navegación!I11,"")
B12: Teléfono/Extensión de contacto del usuario | D12: =IF(Navegación!D12<>"",Navegación!D12,"") | E12: =IF(Navegación!E12<>"",Navegación!E12,"") | F12: =IF(Navegación!F12<>"",Navegación!F12,"") | G12: =IF(Navegación!G12<>"",Navegación!G12,"") | H12: =IF(Navegación!H12<>"",Navegación!H12,"") | I12: =IF(Navegación!I12<>"",Navegación!I12,"")
B13: Celular | D13: =IF(Navegación!D13<>"",Navegación!D13,"") -> 3150727969 | E13: =IF(Navegación!E13<>"",Navegación!E13,"") | F13: =IF(Navegación!F13<>"",Navegación!F13,"") | G13: =IF(Navegación!G13<>"",Navegación!G13,"") | H13: =IF(Navegación!H13<>"",Navegación!H13,"") | I13: =IF(Navegación!I13<>"",Navegación!I13,"")
B14: Dependencia | D14: =IF(Navegación!D14<>"",Navegación!D14,"") -> Gobierno | E14: =IF(Navegación!E14<>"",Navegación!E14,"") | F14: =IF(Navegación!F14<>"",Navegación!F14,"") | G14: =IF(Navegación!G14<>"",Navegación!G14,"") | H14: =IF(Navegación!H14<>"",Navegación!H14,"") | I14: =IF(Navegación!I14<>"",Navegación!I14,"")
B15: Cargo | D15: =IF(Navegación!D15<>"",Navegación!D15,"") -> Aprendiz Universitario | E15: =IF(Navegación!E15<>"",Navegación!E15,"") | F15: =IF(Navegación!F15<>"",Navegación!F15,"") | G15: =IF(Navegación!G15<>"",Navegación!G15,"") | H15: =IF(Navegación!H15<>"",Navegación!H15,"") | I15: =IF(Navegación!I15<>"",Navegación!I15,"")
B16: Empleado Cafam o Externo | D16: =IF(Navegación!D16<>"",Navegación!D16,"") -> Empleado CAFAM | E16: =IF(Navegación!E16<>"",Navegación!E16,"") | F16: =IF(Navegación!F16<>"",Navegación!F16,"") | G16: =IF(Navegación!G16<>"",Navegación!G16,"") | H16: =IF(Navegación!H16<>"",Navegación!H16,"") | I16: =IF(Navegación!I16<>"",Navegación!I16,"")
B17: Nombre de la empresa cuando es Externo | D17: =IF(Navegación!D17<>"",Navegación!D17,"") | E17: =IF(Navegación!E17<>"",Navegación!E17,"") | F17: =IF(Navegación!F17<>"",Navegación!F17,"") | G17: =IF(Navegación!G17<>"",Navegación!G17,"") | H17: =IF(Navegación!H17<>"",Navegación!H17,"") | I17: =IF(Navegación!I17<>"",Navegación!I17,"")
B18: Fecha inicio contrato: | D18: =IF(Navegación!D18<>"",Navegación!D18,"") -> 45849 | E18: =IF(Navegación!E18<>"",Navegación!E18,"") | F18: =IF(Navegación!F18<>"",Navegación!F18,"") | G18: =IF(Navegación!G18<>"",Navegación!G18,"") | H18: =IF(Navegación!H18<>"",Navegación!H18,"") | I18: =IF(Navegación!I18<>"",Navegación!I18,"")
B19: Fecha finalización contrato: (Si es indefinido escribir 31.12.9999) | D19: =IF(Navegación!D19<>"",Navegación!D19,"") | E19: =IF(Navegación!E19<>"",Navegación!E19,"") | F19: =IF(Navegación!F19<>"",Navegación!F19,"") | G19: =IF(Navegación!G19<>"",Navegación!G19,"") | H19: =IF(Navegación!H19<>"",Navegación!H19,"") | I19: =IF(Navegación!I19<>"",Navegación!I19,"")
B20: ENTERPRISE - Validar con Administrador del Aplicativo | D20: =IF(DZ21>0,Navegación!$E$29,"")
B21: Novedad (Crear/Modificación/Inactivar): | DZ21: =COUNTIF(D21:I21,"<>") -> 0
B22: Requiere imprimir informes
B23: Requiere acceso a información confidencial
B24: Requiere agregar o eliminar exámenes
B25: Alias usuario
B26: Sede Asignación
B27: Perfil
B28: Sede Visualización y Acceso de Información
B29: Secciones a las que requiere permiso
B31: Observaciones
B36: ='WINDOWS 1'!$B$37 -> APROBADOR POR: Jefe Dpto. Servicios Compartidos | F36: ='WINDOWS 1'!F37 -> V20 de 26/09/2023 | I36: ="Pág. " &Navegación!B29 & " de " &Navegación!$B$102 -> Pág. 7 de 54
DZ42: =COUNTIF(#REF!,"<>") -> #REF!
DZ51: =COUNTIF(#REF!,"<>") -> #REF!
DZ58: =COUNTIF(D21:I21,"<>") -> 0
DZ62: =COUNTIF(#REF!,"<>") -> #REF!
DZ72: =COUNTIF(D21:I21,"<>") -> 0
DZ82: =COUNTIF(#REF!,"<>") -> #REF!
DZ88: =COUNTIF(#REF!,"<>") -> #REF!
DZ92: =COUNTIF(#REF!,"<>") -> #REF!
DZ96: =COUNTIF(#REF!,"<>") -> #REF!
DZ102: =COUNTIF(#REF!,"<>") -> #REF!
...

Sheet SALUD 5
K1: 2958465
C2: FORMATO: GESTIÓN DE IDENTIDADES
F3: DOCUMENTO USO INTERNO
B5: Las celdas resaltadas en Naranja son campos obligatorios del Formato.
B6: Información Usuarios | D6: Usuario 1 | E6: Usuario 2 | F6: Usuario 3 | G6: Usuario 4 | H6: Usuario 5 | I6: Usuario 6
B7: Tipo de documento | D7: =IF(Navegación!D7<>"",Navegación!D7,"") -> Cédula Ciudadanía | E7: =IF(Navegación!E7<>"",Navegación!E7,"") | F7: =IF(Navegación!F7<>"",Navegación!F7,"") | G7: =IF(Navegación!G7<>"",Navegación!G7,"") | H7: =IF(Navegación!H7<>"",Navegación!H7,"") | I7: =IF(Navegación!I7<>"",Navegación!I7,"")
B8: Identificación | D8: =IF(Navegación!D8<>"",Navegación!D8,"") -> 1001089595 | E8: =IF(Navegación!E8<>"",Navegación!E8,"") | F8: =IF(Navegación!F8<>"",Navegación!F8,"") | G8: =IF(Navegación!G8<>"",Navegación!G8,"") | H8: =IF(Navegación!H8<>"",Navegación!H8,"") | I8: =IF(Navegación!I8<>"",Navegación!I8,"")
B9: Nombres completos | D9: =IF(Navegación!D9<>"",Navegación!D9,"") -> JUAN PABLO | E9: =IF(Navegación!E9<>"",Navegación!E9,"") | F9: =IF(Navegación!F9<>"",Navegación!F9,"") | G9: =IF(Navegación!G9<>"",Navegación!G9,"") | H9: =IF(Navegación!H9<>"",Navegación!H9,"") | I9: =IF(Navegación!I9<>"",Navegación!I9,"")
B10: Apellidos completos | D10: =IF(Navegación!D10<>"",Navegación!D10,"") -> CAMPO TELLEZ | E10: =IF(Navegación!E10<>"",Navegación!E10,"") | F10: =IF(Navegación!F10<>"",Navegación!F10,"") | G10: =IF(Navegación!G10<>"",Navegación!G10,"") | H10: =IF(Navegación!H10<>"",Navegación!H10,"") | I10: =IF(Navegación!I10<>"",Navegación!I10,"")
B11: Centro de costo | D11: =IF(Navegación!D11<>"",Navegación!D11,"") -> 856 | E11: =IF(Navegación!E11<>"",Navegación!E11,"") | F11: =IF(Navegación!F11<>"",Navegación!F11,"") | G11: =IF(Navegación!G11<>"",Navegación!G11,"") | H11: =IF(Navegación!H11<>"",Navegación!H11,"") | I11: =IF(Navegación!I11<>"",Navegación!I11,"")
B12: Teléfono/Extensión de contacto del usuario | D12: =IF(Navegación!D12<>"",Navegación!D12,"") | E12: =IF(Navegación!E12<>"",Navegación!E12,"") | F12: =IF(Navegación!F12<>"",Navegación!F12,"") | G12: =IF(Navegación!G12<>"",Navegación!G12,"") | H12: =IF(Navegación!H12<>"",Navegación!H12,"") | I12: =IF(Navegación!I12<>"",Navegación!I12,"")
B13: Celular | D13: =IF(Navegación!D13<>"",Navegación!D13,"") -> 3150727969 | E13: =IF(Navegación!E13<>"",Navegación!E13,"") | F13: =IF(Navegación!F13<>"",Navegación!F13,"") | G13: =IF(Navegación!G13<>"",Navegación!G13,"") | H13: =IF(Navegación!H13<>"",Navegación!H13,"") | I13: =IF(Navegación!I13<>"",Navegación!I13,"")
B14: Dependencia | D14: =IF(Navegación!D14<>"",Navegación!D14,"") -> Gobierno | E14: =IF(Navegación!E14<>"",Navegación!E14,"") | F14: =IF(Navegación!F14<>"",Navegación!F14,"") | G14: =IF(Navegación!G14<>"",Navegación!G14,"") | H14: =IF(Navegación!H14<>"",Navegación!H14,"") | I14: =IF(Navegación!I14<>"",Navegación!I14,"")
B15: Cargo | D15: =IF(Navegación!D15<>"",Navegación!D15,"") -> Aprendiz Universitario | E15: =IF(Navegación!E15<>"",Navegación!E15,"") | F15: =IF(Navegación!F15<>"",Navegación!F15,"") | G15: =IF(Navegación!G15<>"",Navegación!G15,"") | H15: =IF(Navegación!H15<>"",Navegación!H15,"") | I15: =IF(Navegación!I15<>"",Navegación!I15,"")
B16: Empleado Cafam o Externo | D16: =IF(Navegación!D16<>"",Navegación!D16,"") -> Empleado CAFAM | E16: =IF(Navegación!E16<>"",Navegación!E16,"") | F16: =IF(Navegación!F16<>"",Navegación!F16,"") | G16: =IF(Navegación!G16<>"",Navegación!G16,"") | H16: =IF(Navegación!H16<>"",Navegación!H16,"") | I16: =IF(Navegación!I16<>"",Navegación!I16,"")
B17: Nombre de la empresa cuando es Externo | D17: =IF(Navegación!D17<>"",Navegación!D17,"") | E17: =IF(Navegación!E17<>"",Navegación!E17,"") | F17: =IF(Navegación!F17<>"",Navegación!F17,"") | G17: =IF(Navegación!G17<>"",Navegación!G17,"") | H17: =IF(Navegación!H17<>"",Navegación!H17,"") | I17: =IF(Navegación!I17<>"",Navegación!I17,"")
B18: Fecha inicio contrato: | D18: =IF(Navegación!D18<>"",Navegación!D18,"") -> 45849 | E18: =IF(Navegación!E18<>"",Navegación!E18,"") | F18: =IF(Navegación!F18<>"",Navegación!F18,"") | G18: =IF(Navegación!G18<>"",Navegación!G18,"") | H18: =IF(Navegación!H18<>"",Navegación!H18,"") | I18: =IF(Navegación!I18<>"",Navegación!I18,"")
B19: Fecha finalización contrato: (Si es indefinido escribir 31.12.9999) | D19: =IF(Navegación!D19<>"",Navegación!D19,"") | E19: =IF(Navegación!E19<>"",Navegación!E19,"") | F19: =IF(Navegación!F19<>"",Navegación!F19,"") | G19: =IF(Navegación!G19<>"",Navegación!G19,"") | H19: =IF(Navegación!H19<>"",Navegación!H19,"") | I19: =IF(Navegación!I19<>"",Navegación!I19,"")
B20: Consulta Informacion SICYPROH | D20: =IF(DZ21>0,Navegación!$E$30,"")
B21: Novedad (Asignar/Retirar): (bdd_sicyproh) | DZ21: =COUNTIF(D21:I21,"<>") -> 0
B22: Aplicativo | D22: SICYPROH | E22: SICYPROH | F22: SICYPROH | G22: SICYPROH | H22: SICYPROH | I22: SICYPROH
B23: Alias usuario
B24: Registro profesional
B25: Tipo de Perfil
B26: Perfil | DZ26: =COUNTIF(#REF!,"<>") -> #REF!
B27: Especialidad
B28: Celular
B29: Estado Civil
B30: Fecha de Nacimiento
B31: Dirección
B32: Barrio
B33: SIGESA | D33: =IF(DZ35>0,Navegación!$E$31,"")
